Workbook

Sheet Form Responses 1
A1: Timestamp | B1: NAMA PEGAWAI | C1: Tahun | D1: Bulan | E1: Upload File Lapkin | F1: [Document Studio] Organize Status #lvxiskze | G1: Response Edit URL | H1: Response ID
A2: 44652.594 | B2: M Abdul Muhshi | C2: 2022 | D2: March | E2: https://drive.google.com/open?id=1OQ6zqAevW7iM2tKB7yvfIlycA08N1gJ0
A3: 44652.641 | B3: Wiwi Wilujeng Kusumawati SE, M.M. | C3: 2022 | D3: March | E3: https://drive.google.com/open?id=1KbMugAf8b_5iAreU1_MAHAY8QWrAH_g_
A4: 44652.672 | B4: Muna S.Si | C4: 2022 | D4: March | E4: https://drive.google.com/open?id=1EkHOa1Xj4wlMev1Ufk7kRFV1yVBazWg8
A5: 44652.677 | B5: Wiwi Wilujeng Kusumawati SE, M.M. | C5: 2022 | D5: March | E5: https://drive.google.com/open?id=1tznX9JIDY43h8NtKFQKEoz60b1c3zVfw
A6: 44655.421 | B6: Siswo Pranyoto | C6: 2022 | D6: March | E6: https://drive.google.com/open?id=1YcLGt-9vwBwCySchq3yX9DXaPjbeV9c-
A7: 44655.477 | B7: Sukilan | C7: 2022 | D7: March | E7: https://drive.google.com/open?id=1wcYRlM-gC9A2Aa6sHCf1D2gVy0WEquzv
A8: 44655.487 | B8: Isgiantono | C8: 2022 | D8: March | E8: https://drive.google.com/open?id=14QjYM5H_0bIZbScESIpU5zPr9X0_AZrp
A9: 44655.49 | B9: Nunung Susanti A.Md | C9: 2022 | D9: March | E9: https://drive.google.com/open?id=1pPdBcUCPaB79o88XYLXCAQAlfl6iiuEv
A10: 44655.518 | B10: Nur Kurniawati SST | C10: 2022 | D10: March | E10: https://drive.google.com/open?id=1AxyV8dgxNX-H4xnxvdT-f_T9BwfyLFIA
A11: 44655.522 | B11: Wiwi Wilujeng Kusumawati SE, M.M. | C11: 2022 | D11: March | E11: https://drive.google.com/open?id=133veeSBIu5D7FwGGy8CdlUYT60dT0IHB
A12: 44655.541 | B12: Ani Murwani | C12: 2022 | D12: March | E12: https://drive.google.com/open?id=1tw-hJrhMmLnswaHUc2He54KjzMLN-CaF
A13: 44655.543 | B13: Siswo | C13: 2022 | D13: March | E13: https://drive.google.com/open?id=1-KMlh6K2KXaHN_a4Z23d0AZ8iUhdLDbb
... A593: 45289.411 | B593: Siswo | C593: 2023 | D593: December | E593: https://drive.google.com/open?id=1BS5p8-lHfQOM__rl1IcLf428e4Aepziv
A594: 45293.363 | B594: Ir. Budi Arif Nugroho M.Si. | C594: 2023 | D594: December | E594: https://drive.google.com/open?id=1wg_5l9pJvW07_nZEZYwqRhrG9dePxTw4 | F594: =HYPERLINK("https://drive.google.com/open?id=1V4TGvz085_QBAvEUyDaeNyMolr93zOZK","1 files moved") -> 1 files moved
A595: 45293.439 | B595: Lydia Mirna Wening Handayani | C595: 2023 | D595: December | E595: https://drive.google.com/open?id=1E30S3PlKpaswkTquqedcN2hvR_1_ijOZ | F595: =HYPERLINK("https://drive.google.com/open?id=1sNh5fA93l5peYz5IJKZGEClKmxdv9dcX","1 files moved") -> 1 files moved
A596: 45420.399 | B596: Paramitha Hanifia SST | C596: 2024 | D596: April | E596: https://drive.google.com/open?id=1IYZYedXDVcllI29a__-oCg0YiaOV2zWs | F596: =HYPERLINK("https://drive.google.com/open?id=1YZIPSo9PodNGWCjC1zK15cW1JEByXJ7w","1 files moved") -> 1 files moved
A597: 45420.407 | B597: Nunung Susanti A.Md | C597: 2024 | D597: April | E597: https://drive.google.com/open?id=1zUAKbjeJU9QE8XY10pC4S9bXjgjHqXsM | F597: =HYPERLINK("https://drive.google.com/open?id=1WAbmR1kP-K3GSrnpnC5igzsk9XdBZPD_","1 files moved") -> 1 files moved
A598: 45420.409 | B598: Muna S.Si | C598: 2024 | D598: April | E598: https://drive.google.com/open?id=1wEVcd_9QNiFC7Tz6H8VZzVELbej6v9RC | F598: =HYPERLINK("https://drive.google.com/open?id=1Zryv8yNLErRzmBqkGZTRY6f8oQgaib5M","1 files moved") -> 1 files moved
A599: 45420.409 | B599: Aris Sutikno SE | C599: 2024 | D599: April | E599: https://drive.google.com/open?id=1RZrj7J_90wALRlpOAsVxGSL3rbwjjIop | F599: =HYPERLINK("https://drive.google.com/open?id=1mgwi5IYuDSmdes063EGgEET4VIkt5Ge6","1 files moved") -> 1 files moved
A600: 45420.413 | B600: M. Masykuri Zaen SST | C600: 2024 | D600: April | E600: https://drive.google.com/open?id=11TRTkZh1ZKHu0zwgRf2lLFcdMV0AvAEQ | F600: =HYPERLINK("https://drive.google.com/open?id=1qa1mLZHOuZIAKZUnYIblWo1lTS9NuBTm","1 files moved") -> 1 files moved
A601: 45420.43 | B601: Ani Murwani | C601: 2024 | D601: April | E601: https://drive.google.com/open?id=1NtfWe0nejgTrXmK4ShmBRCKyBT39OSsx | F601: =HYPERLINK("https://drive.google.com/open?id=1bGJWCN7-bZQSl3cMCCd4KJRrHz1r1jve","1 files moved") -> 1 files moved
A602: 45420.43 | B602: Aji Wahyu Ramadhani SST, M.Si | C602: 2024 | D602: April | E602: https://drive.google.com/open?id=1sOXBgQWMfEtPRvgYP2oxaw34LEMEkqrN | F602: =HYPERLINK("https://drive.google.com/open?id=1pM9D8l1ep_C4D6kUFxAGlSX58S2gNWw7","1 files moved") -> 1 files moved
A603: 45420.434 | B603: Ir. Budi Arif Nugroho M.Si. | C603: 2024 | D603: April | E603: https://drive.google.com/open?id=1EEbBOm1H6pv0BIyvJeVWJYq2dmkru_Qb | F603: =HYPERLINK("https://drive.google.com/open?id=1V4TGvz085_QBAvEUyDaeNyMolr93zOZK","1 files moved") -> 1 files moved
A604: 45420.45 | B604: Supriharto | C604: 2024 | D604: April | E604: https://drive.google.com/open?id=1pKHguqDoyMZ1hAW0fb3JxOABwHBjcBpB | F604: =HYPERLINK("https://drive.google.com/open?id=1vt-BVSJOLHBIrsp9094dDz7aTxUYbXOd","1 files moved") -> 1 files moved
A605: 45420.453 | B605: Imam Sugiarto | C605: 2024 | D605: April | E605: https://drive.google.com/open?id=1s-XBTWQGglynePfK4o51eeHTmiX5sGAO | F605: =HYPERLINK("https://drive.google.com/open?id=1BZohlpYH-tCf-m6ifXipKqyT42Gbzhkv","1 files moved") -> 1 files moved
A606: 45420.453 | B606: Supriharto | C606: 2024 | D606: April | E606: https://drive.google.com/open?id=1OEpC0TK672lFPcruM8IFWFBqbwNPyRGt | F606: =HYPERLINK("https://drive.google.com/open?id=1vt-BVSJOLHBIrsp9094dDz7aTxUYbXOd","1 files moved") -> 1 files moved
A607: 45420.481 | B607: Khusnul Khotimah A.Md | C607: 2024 | D607: April | E607: https://drive.google.com/open?id=1u0gtShmzq-BMPCJJQsV5Ka4htLLaWMoD | F607: =HYPERLINK("https://drive.google.com/open?id=1p9rKdY4QkNWIsmYys86EoZpuyIpPfpst","1 files moved") -> 1 files moved
A608: 45420.572 | B608: Herwastuti Dwi Oktaviani A.Md. | C608: 2024 | D608: April | E608: https://drive.google.com/open?id=11p_AQ5udy6GNgGyExtXwVR7fihFE2skx | F608: =HYPERLINK("https://drive.google.com/open?id=1WOu53emjYl9MgCM11eFHkgxwdHlBm2Xz","1 files moved") -> 1 files moved
A609: 45420.572 | B609: Musyafa'ah A.Md | C609: 2024 | D609: April | E609: https://drive.google.com/open?id=1xBasqMQA0isJMJ_zhDcOwX_WvOL2ibKG | F609: =HYPERLINK("https://drive.google.com/open?id=1tJPwF2su0hso4TETThLNHI9_S0dJdbLl","1 files moved") -> 1 files moved
A610: 45420.576 | B610: Ahmad Syahdi Hamid | C610: 2024 | D610: April | E610: https://drive.google.com/open?id=1dMe_96oco43aerKrHOZJ-7r1tpRa4hur | F610: =HYPERLINK("https://drive.google.com/open?id=1V9JxAml7o3RDV4BK_aYYG2UrIwxiEXjP","1 files moved") -> 1 files moved
A611: 45420.655 | B611: M Abdul Muhshi | C611: 2024 | D611: April | E611: https://drive.google.com/open?id=1nq50HJt16m2EJ0EIbSrlK8RleJKOCwNW | F611: =HYPERLINK("https://drive.google.com/open?id=1RzBx4e3LIUFyXvV8TKxHGhvZPq7MCFk3","1 files moved") -> 1 files moved | G611: https://docs.google.com/forms/d/e/1FAIpQLSeEYwFnViiqk1AbexVe1VDR73UApmeuvfn6Yr2vN8WXjwGu2Q/viewform?edit2=2_ABaOnueSKd-kzOcFA6R4jUnbfDtpCDe86JsxVK3n4FF8zt4KKnL8FRk_PJ8WUeZqa8aDIFc&source=documentstudio&timestamp=1715157834093 | H611: 2_ABaOnueSKd-kzOcFA6R4jUnbfDtpCDe86JsxVK3n4FF8zt4KKnL8FRk_PJ8WUeZqa8aDIFc
A612: 45425.382 | B612: Edy Budi Utomo SE. | C612: 2024 | D612: April | E612: https://drive.google.com/open?id=1-4Xx1YcTjfP0lcyW843pXvnkw-6zGlv0 | F612: =HYPERLINK("https://drive.google.com/open?id=1CSWuwAcjfOUkpFz17anJSHXpLD9oH9ta","1 files moved") -> 1 files moved | G612: https://docs.google.com/forms/d/e/1FAIpQLSeEYwFnViiqk1AbexVe1VDR73UApmeuvfn6Yr2vN8WXjwGu2Q/viewform?edit2=2_ABaOnuckTyf2Hnfuh02o49q_VmQBnHx0EbJumv1fjsKum_kywTqkc4tmnvTQ7wHYhp4RhBc&source=documentstudio&timestamp=1715566209355 | H612: 2_ABaOnuckTyf2Hnfuh02o49q_VmQBnHx0EbJumv1fjsKum_kywTqkc4tmnvTQ7wHYhp4RhBc
A613: 45425.388 | B613: M Abdul Aziz | C613: 2024 | D613: April | E613: https://drive.google.com/open?id=1EWPYiFbe6eGT9Q28R2Huma67a2gfJ1eQ | F613: =HYPERLINK("https://drive.google.com/open?id=1YKXc634Hd6ivOmY-kuk_dNKkhypgkHlR","1 files moved") -> 1 files moved | G613: https://docs.google.com/forms/d/e/1FAIpQLSeEYwFnViiqk1AbexVe1VDR73UApmeuvfn6Yr2vN8WXjwGu2Q/viewform?edit2=2_ABaOnufvDvMB4fEqodsNL2i5_8gXfcEhhtoEfH0C6YPnu8GvEtGgxWfK4u5sVCD5pxHWC3s&source=documentstudio&timestamp=1715566745763 | H613: 2_ABaOnufvDvMB4fEqodsNL2i5_8gXfcEhhtoEfH0C6YPnu8GvEtGgxWfK4u5sVCD5pxHWC3s
A614: 45426.38 | B614: Moh.Saiful Hidayah Brotowiyono | C614: 2024 | D614: April | E614: https://drive.google.com/open?id=1otLQm73PTiDOB7G6eFJqgt6MlVug4Bz2 | F614: =HYPERLINK("https://drive.google.com/open?id=11skWmlW9bg1I5Y0qbtAwiD9dgHdxhUYl","1 files moved") -> 1 files moved | G614: https://docs.google.com/forms/d/e/1FAIpQLSeEYwFnViiqk1AbexVe1VDR73UApmeuvfn6Yr2vN8WXjwGu2Q/viewform?edit2=2_ABaOnufFuUljUfVMlDA9uICkOb6JqE5YnPiYWbkLxOcYIe_ysYIZGwP034XD6_0POHhPzD4&source=documentstudio&timestamp=1715652473302 | H614: 2_ABaOnufFuUljUfVMlDA9uICkOb6JqE5YnPiYWbkLxOcYIe_ysYIZGwP034XD6_0POHhPzD4
A615: 45426.446 | B615: Sucipto | C615: 2024 | D615: April | E615: https://drive.google.com/open?id=1tKoj864zW7mCk6iO3DUB8IOh0DloeaPI | F615: =HYPERLINK("https://drive.google.com/open?id=17WOaAXl5jFgeySypAmjW1SMD0z4Hcu1k","1 files moved") -> 1 files moved | G615: https://docs.google.com/forms/d/e/1FAIpQLSeEYwFnViiqk1AbexVe1VDR73UApmeuvfn6Yr2vN8WXjwGu2Q/viewform?edit2=2_ABaOnueH7iAnkym5HUZ6n6x7Bp3k4F8QaXVXIT-NL57IyiRnQpVk4A0tiDdKhT7QRg_SuCg&source=documentstudio&timestamp=1715658171887 | H615: 2_ABaOnueH7iAnkym5HUZ6n6x7Bp3k4F8QaXVXIT-NL57IyiRnQpVk4A0tiDdKhT7QRg_SuCg
A616: 45426.448 | B616: Siswo Pranyoto | C616: 2024 | D616: April | E616: https://drive.google.com/open?id=1r3utf0PLI_FB1WWEkTFIqznYS3LogvnU | F616: =HYPERLINK("https://drive.google.com/open?id=1YNQBM17-ejVScp5nWkNR2hYKrlehzOCe","1 files moved") -> 1 files moved | G616: https://docs.google.com/forms/d/e/1FAIpQLSeEYwFnViiqk1AbexVe1VDR73UApmeuvfn6Yr2vN8WXjwGu2Q/viewform?edit2=2_ABaOnuftjKx08Rq4RRZoegl3Xe4awRLHuXoDbM78AiV47aAQu7Mhor022fmgGX4NhDNNS7w&source=documentstudio&timestamp=1715658279463 | H616: 2_ABaOnuftjKx08Rq4RRZoegl3Xe4awRLHuXoDbM78AiV47aAQu7Mhor022fmgGX4NhDNNS7w
A617: 45427.594 | B617: Dyah Makutaning Dewi | C617: 2024 | D617: April | E617: https://drive.google.com/open?id=1ZS6X8dWDXQPyxfyNoCkUrNTYVBzWKSG3 | F617: =HYPERLINK("https://drive.google.com/open?id=1raKDx-uNeIvhNP7U_Rt7B4uGTAH17pUT","1 files moved") -> 1 files moved | G617: https://docs.google.com/forms/d/e/1FAIpQLSeEYwFnViiqk1AbexVe1VDR73UApmeuvfn6Yr2vN8WXjwGu2Q/viewform?edit2=2_ABaOnueWqhaPJPCgq_dJBg_V0VTwiz4axeJwVRJ0oQ3KqRG-9eokY6wQRdfh1Xe97i2bRLE&source=documentstudio&timestamp=1715757323319 | H617: 2_ABaOnueWqhaPJPCgq_dJBg_V0VTwiz4axeJwVRJ0oQ3KqRG-9eokY6wQRdfh1Xe97i2bRLE
A618: 45427.624 | B618: Nur Kurniawati SST | C618: 2024 | D618: April | E618: https://drive.google.com/open?id=1aJwhmF55_qDOJRz8cOccZp40wSiAwVi6 | F618: =HYPERLINK("https://drive.google.com/open?id=1lAkCTSJDqjfWsuZxvLL2COI53gbRENb_","1 files moved") -> 1 files moved | G618: https://docs.google.com/forms/d/e/1FAIpQLSeEYwFnViiqk1AbexVe1VDR73UApmeuvfn6Yr2vN8WXjwGu2Q/viewform?edit2=2_ABaOnudOsCpur2_UHH1bhflK-CH8C4irFSat0rG-TpK2y-ERCAj_0ot2hLLhWPGlnqdmvE8&source=documentstudio&timestamp=1715759946673 | H618: 2_ABaOnudOsCpur2_UHH1bhflK-CH8C4irFSat0rG-TpK2y-ERCAj_0ot2hLLhWPGlnqdmvE8
A619: 45429.303 | B619: Abdul Khalim | C619: 2024 | D619: April | E619: https://drive.google.com/open?id=1wUWs9AMZLUEcWapr_iL8EiMmWzi97tUg | F619: =HYPERLINK("https://drive.google.com/open?id=1OV29wdO4ju235Dn_RfWfQvZfv8o_gJRA","1 files moved") -> 1 files moved | G619: https://docs.google.com/forms/d/e/1FAIpQLSeEYwFnViiqk1AbexVe1VDR73UApmeuvfn6Yr2vN8WXjwGu2Q/viewform?edit2=2_ABaOnudLs7rXiLFVtSHnuWvHhF9zXZbDcSsGju8Cpg1DoXGfrMx3QpGm1OU8vrM1fnxJrVE&source=documentstudio&timestamp=1715904985006 | H619: 2_ABaOnudLs7rXiLFVtSHnuWvHhF9zXZbDcSsGju8Cpg1DoXGfrMx3QpGm1OU8vrM1fnxJrVE
...

Sheet Monitoring
C1: 2024 | S1: 2025 | AE1: 2025 | AG1: 2026
A2: No | B2: Nama Pegawai | C2: March | D2: April | E2: May | F2: June | G2: July | H2: August | I2: September | J2: October | K2: November | L2: December | M2: Tahunan | N2: March Excel | O2: Tahunan Penilaian | P2: Tahunan Dokumen Evaluasi | Q2: Tahunan Penetapan Excel/IKI | R2: Tahunan Penetapan | S2: January | T2: February | U2: March | V2: April | W2: May | X2: June | Y2: July | Z2: August | AA2: September | AB2: October | AC2: November | AD2: December | AE2: Tahunan Dokumen Evaluasi | AF2: Tahunan Penilaian | AG2: Tahunan Penetapan Excel/IKI | AH2: Tahunan Penetapan | AI2: January | AJ2: February | AK2: March | AL2: April | AM2: May | AN2: June | AO2: July | AP2: August | AQ2: September | AR2: October | AS2: November | AT2: December | AU2: Tahunan Dokumen Evaluasi
A3: 1 | B3: Khomarudin | C3: =IF(COUNTIFS('Form Responses 1'!$B:$B,$B3,'Form Responses 1'!$C:$C,2024,'Form Responses 1'!$D:$D,C$2)>0,TRUE) -> FALSE | D3: =IF(COUNTIFS('Form Responses 1'!$B:$B,$B3,'Form Responses 1'!$C:$C,2024,'Form Responses 1'!$D:$D,D$2)>0,TRUE) -> FALSE | E3: =IF(COUNTIFS('Form Responses 1'!$B:$B,$B3,'Form Responses 1'!$C:$C,2024,'Form Responses 1'!$D:$D,E$2)>0,TRUE) -> FALSE | F3: =IF(COUNTIFS('Form Responses 1'!$B:$B,$B3,'Form Responses 1'!$C:$C,2024,'Form Responses 1'!$D:$D,F$2)>0,TRUE) -> FALSE | G3: =IF(COUNTIFS('Form Responses 1'!$B:$B,$B3,'Form Responses 1'!$C:$C,2024,'Form Responses 1'!$D:$D,G$2)>0,TRUE) -> FALSE | H3: =IF(COUNTIFS('Form Responses 1'!$B:$B,$B3,'Form Responses 1'!$C:$C,2024,'Form Responses 1'!$D:$D,H$2)>0,TRUE) -> FALSE | I3: =IF(COUNTIFS('Form Responses 1'!$B:$B,$B3,'Form Responses 1'!$C:$C,2024,'Form Responses 1'!$D:$D,I$2)>0,TRUE) -> FALSE | J3: =IF(COUNTIFS('Form Responses 1'!$B:$B,$B3,'Form Responses 1'!$C:$C,2024,'Form Responses 1'!$D:$D,J$2)>0,TRUE) -> FALSE | ... P3: =IF(COUNTIFS('Form Responses 1'!$B:$B,$B3,'Form Responses 1'!$C:$C,2024,'Form Responses 1'!$D:$D,P$2)>0,TRUE) -> FALSE | Q3: FALSE | R3: FALSE | S3: =IF(COUNTIFS('Form Responses 1'!$B:$B,$B3,'Form Responses 1'!$C:$C,2025,'Form Responses 1'!$D:$D,S$2)>0,TRUE) -> TRUE | T3: =IF(COUNTIFS('Form Responses 1'!$B:$B,$B3,'Form Responses 1'!$C:$C,2025,'Form Responses 1'!$D:$D,T$2)>0,TRUE) -> TRUE | U3: =IF(COUNTIFS('Form Responses 1'!$B:$B,$B3,'Form Responses 1'!$C:$C,2025,'Form Responses 1'!$D:$D,U$2)>0,TRUE) -> TRUE | V3: =IF(COUNTIFS('Form Responses 1'!$B:$B,$B3,'Form Responses 1'!$C:$C,2025,'Form Responses 1'!$D:$D,V$2)>0,TRUE) -> TRUE | W3: =IF(COUNTIFS('Form Responses 1'!$B:$B,$B3,'Form Responses 1'!$C:$C,2025,'Form Responses 1'!$D:$D,W$2)>0,TRUE) -> TRUE | X3: =IF(COUNTIFS('Form Responses 1'!$B:$B,$B3,'Form Responses 1'!$C:$C,2025,'Form Responses 1'!$D:$D,X$2)>0,TRUE) -> TRUE | Y3: =IF(COUNTIFS('Form Responses 1'!$B:$B,$B3,'Form Responses 1'!$C:$C,2025,'Form Responses 1'!$D:$D,Y$2)>0,TRUE) -> TRUE | Z3: =IF(COUNTIFS('Form Responses 1'!$B:$B,$B3,'Form Responses 1'!$C:$C,2025,'Form Responses 1'!$D:$D,Z$2)>0,TRUE) -> TRUE | ... AF3: =IF(COUNTIFS('Form Responses 1'!$B:$B,$B3,'Form Responses 1'!$C:$C,2025,'Form Responses 1'!$D:$D,AF$2)>0,TRUE) -> TRUE | AG3: =IF(COUNTIFS('Form Responses 1'!$B:$B,$B3,'Form Responses 1'!$C:$C,2026,'Form Responses 1'!$D:$D,AG$2)>0,TRUE) -> FALSE | AH3: =IF(COUNTIFS('Form Responses 1'!$B:$B,$B3,'Form Responses 1'!$C:$C,2026,'Form Responses 1'!$D:$D,AH$2)>0,TRUE) -> FALSE | AI3: =IF(COUNTIFS('Form Responses 1'!$B:$B,$B3,'Form Responses 1'!$C:$C,2026,'Form Responses 1'!$D:$D,AI$2)>0,TRUE) -> FALSE | AJ3: =IF(COUNTIFS('Form Responses 1'!$B:$B,$B3,'Form Responses 1'!$C:$C,2026,'Form Responses 1'!$D:$D,AJ$2)>0,TRUE) -> FALSE | AK3: =IF(COUNTIFS('Form Responses 1'!$B:$B,$B3,'Form Responses 1'!$C:$C,2026,'Form Responses 1'!$D:$D,AK$2)>0,TRUE) -> FALSE | AL3: =IF(COUNTIFS('Form Responses 1'!$B:$B,$B3,'Form Responses 1'!$C:$C,2026,'Form Responses 1'!$D:$D,AL$2)>0,TRUE) -> FALSE | AM3: =IF(COUNTIFS('Form Responses 1'!$B:$B,$B3,'Form Responses 1'!$C:$C,2026,'Form Responses 1'!$D:$D,AM$2)>0,TRUE) -> FALSE | AN3: =IF(COUNTIFS('Form Responses 1'!$B:$B,$B3,'Form Responses 1'!$C:$C,2026,'Form Responses 1'!$D:$D,AN$2)>0,TRUE) -> FALSE | ... AU3: =IF(COUNTIFS('Form Responses 1'!$B:$B,$B3,'Form Responses 1'!$C:$C,2026,'Form Responses 1'!$D:$D,AU$2)>0,TRUE) -> FALSE
A4: 2 | B4: M. Masykuri Zaen SST | C4: =IF(COUNTIFS('Form Responses 1'!$B:$B,$B4,'Form Responses 1'!$C:$C,2024,'Form Responses 1'!$D:$D,C$2)>0,TRUE) -> FALSE | D4: =IF(COUNTIFS('Form Responses 1'!$B:$B,$B4,'Form Responses 1'!$C:$C,2024,'Form Responses 1'!$D:$D,D$2)>0,TRUE) -> TRUE | E4: =IF(COUNTIFS('Form Responses 1'!$B:$B,$B4,'Form Responses 1'!$C:$C,2024,'Form Responses 1'!$D:$D,E$2)>0,TRUE) -> TRUE | F4: =IF(COUNTIFS('Form Responses 1'!$B:$B,$B4,'Form Responses 1'!$C:$C,2024,'Form Responses 1'!$D:$D,F$2)>0,TRUE) -> TRUE | G4: =IF(COUNTIFS('Form Responses 1'!$B:$B,$B4,'Form Responses 1'!$C:$C,2024,'Form Responses 1'!$D:$D,G$2)>0,TRUE) -> TRUE | H4: =IF(COUNTIFS('Form Responses 1'!$B:$B,$B4,'Form Responses 1'!$C:$C,2024,'Form Responses 1'!$D:$D,H$2)>0,TRUE) -> TRUE | I4: =IF(COUNTIFS('Form Responses 1'!$B:$B,$B4,'Form Responses 1'!$C:$C,2024,'Form Responses 1'!$D:$D,I$2)>0,TRUE) -> TRUE | J4: =IF(COUNTIFS('Form Responses 1'!$B:$B,$B4,'Form Responses 1'!$C:$C,2024,'Form Responses 1'!$D:$D,J$2)>0,TRUE) -> TRUE | ... P4: =IF(COUNTIFS('Form Responses 1'!$B:$B,$B4,'Form Responses 1'!$C:$C,2024,'Form Responses 1'!$D:$D,P$2)>0,TRUE) -> TRUE | Q4: =IF(COUNTIFS('Form Responses 1'!$B:$B,$B4,'Form Responses 1'!$C:$C,2025,'Form Responses 1'!$D:$D,Q$2)>0,TRUE) -> TRUE | R4: =IF(COUNTIFS('Form Responses 1'!$B:$B,$B4,'Form Responses 1'!$C:$C,2025,'Form Responses 1'!$D:$D,R$2)>0,TRUE) -> TRUE | S4: =IF(COUNTIFS('Form Responses 1'!$B:$B,$B4,'Form Responses 1'!$C:$C,2025,'Form Responses 1'!$D:$D,S$2)>0,TRUE) -> TRUE | T4: =IF(COUNTIFS('Form Responses 1'!$B:$B,$B4,'Form Responses 1'!$C:$C,2025,'Form Responses 1'!$D:$D,T$2)>0,TRUE) -> TRUE | U4: =IF(COUNTIFS('Form Responses 1'!$B:$B,$B4,'Form Responses 1'!$C:$C,2025,'Form Responses 1'!$D:$D,U$2)>0,TRUE) -> TRUE | V4: =IF(COUNTIFS('Form Responses 1'!$B:$B,$B4,'Form Responses 1'!$C:$C,2025,'Form Responses 1'!$D:$D,V$2)>0,TRUE) -> TRUE | W4: =IF(COUNTIFS('Form Responses 1'!$B:$B,$B4,'Form Responses 1'!$C:$C,2025,'Form Responses 1'!$D:$D,W$2)>0,TRUE) -> TRUE | X4: =IF(COUNTIFS('Form Responses 1'!$B:$B,$B4,'Form Responses 1'!$C:$C,2025,'Form Responses 1'!$D:$D,X$2)>0,TRUE) -> TRUE | ... AF4: =IF(COUNTIFS('Form Responses 1'!$B:$B,$B4,'Form Responses 1'!$C:$C,2025,'Form Responses 1'!$D:$D,AF$2)>0,TRUE) -> TRUE | AG4: =IF(COUNTIFS('Form Responses 1'!$B:$B,$B4,'Form Responses 1'!$C:$C,2026,'Form Responses 1'!$D:$D,AG$2)>0,TRUE) -> FALSE | AH4: =IF(COUNTIFS('Form Responses 1'!$B:$B,$B4,'Form Responses 1'!$C:$C,2026,'Form Responses 1'!$D:$D,AH$2)>0,TRUE) -> FALSE | AI4: =IF(COUNTIFS('Form Responses 1'!$B:$B,$B4,'Form Responses 1'!$C:$C,2026,'Form Responses 1'!$D:$D,AI$2)>0,TRUE) -> FALSE | AJ4: =IF(COUNTIFS('Form Responses 1'!$B:$B,$B4,'Form Responses 1'!$C:$C,2026,'Form Responses 1'!$D:$D,AJ$2)>0,TRUE) -> FALSE | AK4: =IF(COUNTIFS('Form Responses 1'!$B:$B,$B4,'Form Responses 1'!$C:$C,2026,'Form Responses 1'!$D:$D,AK$2)>0,TRUE) -> FALSE | AL4: =IF(COUNTIFS('Form Responses 1'!$B:$B,$B4,'Form Responses 1'!$C:$C,2026,'Form Responses 1'!$D:$D,AL$2)>0,TRUE) -> FALSE | AM4: =IF(COUNTIFS('Form Responses 1'!$B:$B,$B4,'Form Responses 1'!$C:$C,2026,'Form Responses 1'!$D:$D,AM$2)>0,TRUE) -> FALSE | AN4: =IF(COUNTIFS('Form Responses 1'!$B:$B,$B4,'Form Responses 1'!$C:$C,2026,'Form Responses 1'!$D:$D,AN$2)>0,TRUE) -> FALSE | ... AU4: =IF(COUNTIFS('Form Responses 1'!$B:$B,$B4,'Form Responses 1'!$C:$C,2026,'Form Responses 1'!$D:$D,AU$2)>0,TRUE) -> FALSE
A5: 3 | B5: Moh.Saiful Hidayah Brotowiyono | C5: =IF(COUNTIFS('Form Responses 1'!$B:$B,$B5,'Form Responses 1'!$C:$C,2024,'Form Responses 1'!$D:$D,C$2)>0,TRUE) -> TRUE | D5: =IF(COUNTIFS('Form Responses 1'!$B:$B,$B5,'Form Responses 1'!$C:$C,2024,'Form Responses 1'!$D:$D,D$2)>0,TRUE) -> TRUE | E5: =IF(COUNTIFS('Form Responses 1'!$B:$B,$B5,'Form Responses 1'!$C:$C,2024,'Form Responses 1'!$D:$D,E$2)>0,TRUE) -> TRUE | F5: =IF(COUNTIFS('Form Responses 1'!$B:$B,$B5,'Form Responses 1'!$C:$C,2024,'Form Responses 1'!$D:$D,F$2)>0,TRUE) -> TRUE | G5: =IF(COUNTIFS('Form Responses 1'!$B:$B,$B5,'Form Responses 1'!$C:$C,2024,'Form Responses 1'!$D:$D,G$2)>0,TRUE) -> TRUE | H5: =IF(COUNTIFS('Form Responses 1'!$B:$B,$B5,'Form Responses 1'!$C:$C,2024,'Form Responses 1'!$D:$D,H$2)>0,TRUE) -> TRUE | I5: =IF(COUNTIFS('Form Responses 1'!$B:$B,$B5,'Form Responses 1'!$C:$C,2024,'Form Responses 1'!$D:$D,I$2)>0,TRUE) -> TRUE | J5: =IF(COUNTIFS('Form Responses 1'!$B:$B,$B5,'Form Responses 1'!$C:$C,2024,'Form Responses 1'!$D:$D,J$2)>0,TRUE) -> TRUE | ... P5: =IF(COUNTIFS('Form Responses 1'!$B:$B,$B5,'Form Responses 1'!$C:$C,2024,'Form Responses 1'!$D:$D,P$2)>0,TRUE) -> TRUE | Q5: =IF(COUNTIFS('Form Responses 1'!$B:$B,$B5,'Form Responses 1'!$C:$C,2025,'Form Responses 1'!$D:$D,Q$2)>0,TRUE) -> TRUE | R5: =IF(COUNTIFS('Form Responses 1'!$B:$B,$B5,'Form Responses 1'!$C:$C,2025,'Form Responses 1'!$D:$D,R$2)>0,TRUE) -> TRUE | S5: =IF(COUNTIFS('Form Responses 1'!$B:$B,$B5,'Form Responses 1'!$C:$C,2025,'Form Responses 1'!$D:$D,S$2)>0,TRUE) -> TRUE | T5: =IF(COUNTIFS('Form Responses 1'!$B:$B,$B5,'Form Responses 1'!$C:$C,2025,'Form Responses 1'!$D:$D,T$2)>0,TRUE) -> TRUE | U5: =IF(COUNTIFS('Form Responses 1'!$B:$B,$B5,'Form Responses 1'!$C:$C,2025,'Form Responses 1'!$D:$D,U$2)>0,TRUE) -> TRUE | V5: =IF(COUNTIFS('Form Responses 1'!$B:$B,$B5,'Form Responses 1'!$C:$C,2025,'Form Responses 1'!$D:$D,V$2)>0,TRUE) -> TRUE | W5: =IF(COUNTIFS('Form Responses 1'!$B:$B,$B5,'Form Responses 1'!$C:$C,2025,'Form Responses 1'!$D:$D,W$2)>0,TRUE) -> TRUE | X5: =IF(COUNTIFS('Form Responses 1'!$B:$B,$B5,'Form Responses 1'!$C:$C,2025,'Form Responses 1'!$D:$D,X$2)>0,TRUE) -> TRUE | ... AF5: =IF(COUNTIFS('Form Responses 1'!$B:$B,$B5,'Form Responses 1'!$C:$C,2025,'Form Responses 1'!$D:$D,AF$2)>0,TRUE) -> TRUE | AG5: =IF(COUNTIFS('Form Responses 1'!$B:$B,$B5,'Form Responses 1'!$C:$C,2026,'Form Responses 1'!$D:$D,AG$2)>0,TRUE) -> FALSE | AH5: =IF(COUNTIFS('Form Responses 1'!$B:$B,$B5,'Form Responses 1'!$C:$C,2026,'Form Responses 1'!$D:$D,AH$2)>0,TRUE) -> FALSE | AI5: =IF(COUNTIFS('Form Responses 1'!$B:$B,$B5,'Form Responses 1'!$C:$C,2026,'Form Responses 1'!$D:$D,AI$2)>0,TRUE) -> FALSE | AJ5: =IF(COUNTIFS('Form Responses 1'!$B:$B,$B5,'Form Responses 1'!$C:$C,2026,'Form Responses 1'!$D:$D,AJ$2)>0,TRUE) -> FALSE | AK5: =IF(COUNTIFS('Form Responses 1'!$B:$B,$B5,'Form Responses 1'!$C:$C,2026,'Form Responses 1'!$D:$D,AK$2)>0,TRUE) -> FALSE | AL5: =IF(COUNTIFS('Form Responses 1'!$B:$B,$B5,'Form Responses 1'!$C:$C,2026,'Form Responses 1'!$D:$D,AL$2)>0,TRUE) -> FALSE | AM5: =IF(COUNTIFS('Form Responses 1'!$B:$B,$B5,'Form Responses 1'!$C:$C,2026,'Form Responses 1'!$D:$D,AM$2)>0,TRUE) -> FALSE | AN5: =IF(COUNTIFS('Form Responses 1'!$B:$B,$B5,'Form Responses 1'!$C:$C,2026,'Form Responses 1'!$D:$D,AN$2)>0,TRUE) -> FALSE | ... AU5: =IF(COUNTIFS('Form Responses 1'!$B:$B,$B5,'Form Responses 1'!$C:$C,2026,'Form Responses 1'!$D:$D,AU$2)>0,TRUE) -> FALSE
A6: 4 | B6: Paramitha Hanifia SST | C6: =IF(COUNTIFS('Form Responses 1'!$B:$B,$B6,'Form Responses 1'!$C:$C,2024,'Form Responses 1'!$D:$D,C$2)>0,TRUE) -> FALSE | D6: =IF(COUNTIFS('Form Responses 1'!$B:$B,$B6,'Form Responses 1'!$C:$C,2024,'Form Responses 1'!$D:$D,D$2)>0,TRUE) -> TRUE | E6: =IF(COUNTIFS('Form Responses 1'!$B:$B,$B6,'Form Responses 1'!$C:$C,2024,'Form Responses 1'!$D:$D,E$2)>0,TRUE) -> TRUE | F6: =IF(COUNTIFS('Form Responses 1'!$B:$B,$B6,'Form Responses 1'!$C:$C,2024,'Form Responses 1'!$D:$D,F$2)>0,TRUE) -> TRUE | G6: =IF(COUNTIFS('Form Responses 1'!$B:$B,$B6,'Form Responses 1'!$C:$C,2024,'Form Responses 1'!$D:$D,G$2)>0,TRUE) -> TRUE | H6: =IF(COUNTIFS('Form Responses 1'!$B:$B,$B6,'Form Responses 1'!$C:$C,2024,'Form Responses 1'!$D:$D,H$2)>0,TRUE) -> TRUE | I6: =IF(COUNTIFS('Form Responses 1'!$B:$B,$B6,'Form Responses 1'!$C:$C,2024,'Form Responses 1'!$D:$D,I$2)>0,TRUE) -> TRUE | J6: =IF(COUNTIFS('Form Responses 1'!$B:$B,$B6,'Form Responses 1'!$C:$C,2024,'Form Responses 1'!$D:$D,J$2)>0,TRUE) -> TRUE | ... P6: =IF(COUNTIFS('Form Responses 1'!$B:$B,$B6,'Form Responses 1'!$C:$C,2024,'Form Responses 1'!$D:$D,P$2)>0,TRUE) -> TRUE | Q6: =IF(COUNTIFS('Form Responses 1'!$B:$B,$B6,'Form Responses 1'!$C:$C,2025,'Form Responses 1'!$D:$D,Q$2)>0,TRUE) -> TRUE | R6: =IF(COUNTIFS('Form Responses 1'!$B:$B,$B6,'Form Responses 1'!$C:$C,2025,'Form Responses 1'!$D:$D,R$2)>0,TRUE) -> TRUE | S6: =IF(COUNTIFS('Form Responses 1'!$B:$B,$B6,'Form Responses 1'!$C:$C,2025,'Form Responses 1'!$D:$D,S$2)>0,TRUE) -> TRUE | T6: =IF(COUNTIFS('Form Responses 1'!$B:$B,$B6,'Form Responses 1'!$C:$C,2025,'Form Responses 1'!$D:$D,T$2)>0,TRUE) -> TRUE | U6: =IF(COUNTIFS('Form Responses 1'!$B:$B,$B6,'Form Responses 1'!$C:$C,2025,'Form Responses 1'!$D:$D,U$2)>0,TRUE) -> TRUE | V6: =IF(COUNTIFS('Form Responses 1'!$B:$B,$B6,'Form Responses 1'!$C:$C,2025,'Form Responses 1'!$D:$D,V$2)>0,TRUE) -> TRUE | W6: =IF(COUNTIFS('Form Responses 1'!$B:$B,$B6,'Form Responses 1'!$C:$C,2025,'Form Responses 1'!$D:$D,W$2)>0,TRUE) -> TRUE | X6: =IF(COUNTIFS('Form Responses 1'!$B:$B,$B6,'Form Responses 1'!$C:$C,2025,'Form Responses 1'!$D:$D,X$2)>0,TRUE) -> TRUE | ... AF6: =IF(COUNTIFS('Form Responses 1'!$B:$B,$B6,'Form Responses 1'!$C:$C,2025,'Form Responses 1'!$D:$D,AF$2)>0,TRUE) -> TRUE | AG6: =IF(COUNTIFS('Form Responses 1'!$B:$B,$B6,'Form Responses 1'!$C:$C,2026,'Form Responses 1'!$D:$D,AG$2)>0,TRUE) -> FALSE | AH6: =IF(COUNTIFS('Form Responses 1'!$B:$B,$B6,'Form Responses 1'!$C:$C,2026,'Form Responses 1'!$D:$D,AH$2)>0,TRUE) -> FALSE | AI6: =IF(COUNTIFS('Form Responses 1'!$B:$B,$B6,'Form Responses 1'!$C:$C,2026,'Form Responses 1'!$D:$D,AI$2)>0,TRUE) -> FALSE | AJ6: =IF(COUNTIFS('Form Responses 1'!$B:$B,$B6,'Form Responses 1'!$C:$C,2026,'Form Responses 1'!$D:$D,AJ$2)>0,TRUE) -> FALSE | AK6: =IF(COUNTIFS('Form Responses 1'!$B:$B,$B6,'Form Responses 1'!$C:$C,2026,'Form Responses 1'!$D:$D,AK$2)>0,TRUE) -> FALSE | AL6: =IF(COUNTIFS('Form Responses 1'!$B:$B,$B6,'Form Responses 1'!$C:$C,2026,'Form Responses 1'!$D:$D,AL$2)>0,TRUE) -> FALSE | AM6: =IF(COUNTIFS('Form Responses 1'!$B:$B,$B6,'Form Responses 1'!$C:$C,2026,'Form Responses 1'!$D:$D,AM$2)>0,TRUE) -> FALSE | AN6: =IF(COUNTIFS('Form Responses 1'!$B:$B,$B6,'Form Responses 1'!$C:$C,2026,'Form Responses 1'!$D:$D,AN$2)>0,TRUE) -> FALSE | ... AU6: =IF(COUNTIFS('Form Responses 1'!$B:$B,$B6,'Form Responses 1'!$C:$C,2026,'Form Responses 1'!$D:$D,AU$2)>0,TRUE) -> FALSE
A7: 5 | B7: Wiwi Wilujeng Kusumawati SE, M.M. | C7: =IF(COUNTIFS('Form Responses 1'!$B:$B,$B7,'Form Responses 1'!$C:$C,2024,'Form Responses 1'!$D:$D,C$2)>0,TRUE) -> TRUE | D7: =IF(COUNTIFS('Form Responses 1'!$B:$B,$B7,'Form Responses 1'!$C:$C,2024,'Form Responses 1'!$D:$D,D$2)>0,TRUE) -> TRUE | E7: =IF(COUNTIFS('Form Responses 1'!$B:$B,$B7,'Form Responses 1'!$C:$C,2024,'Form Responses 1'!$D:$D,E$2)>0,TRUE) -> TRUE | F7: =IF(COUNTIFS('Form Responses 1'!$B:$B,$B7,'Form Responses 1'!$C:$C,2024,'Form Responses 1'!$D:$D,F$2)>0,TRUE) -> TRUE | G7: =IF(COUNTIFS('Form Responses 1'!$B:$B,$B7,'Form Responses 1'!$C:$C,2024,'Form Responses 1'!$D:$D,G$2)>0,TRUE) -> TRUE | H7: =IF(COUNTIFS('Form Responses 1'!$B:$B,$B7,'Form Responses 1'!$C:$C,2024,'Form Responses 1'!$D:$D,H$2)>0,TRUE) -> TRUE | I7: =IF(COUNTIFS('Form Responses 1'!$B:$B,$B7,'Form Responses 1'!$C:$C,2024,'Form Responses 1'!$D:$D,I$2)>0,TRUE) -> TRUE | J7: =IF(COUNTIFS('Form Responses 1'!$B:$B,$B7,'Form Responses 1'!$C:$C,2024,'Form Responses 1'!$D:$D,J$2)>0,TRUE) -> TRUE | ... P7: =IF(COUNTIFS('Form Responses 1'!$B:$B,$B7,'Form Responses 1'!$C:$C,2024,'Form Responses 1'!$D:$D,P$2)>0,TRUE) -> TRUE | Q7: =IF(COUNTIFS('Form Responses 1'!$B:$B,$B7,'Form Responses 1'!$C:$C,2025,'Form Responses 1'!$D:$D,Q$2)>0,TRUE) -> TRUE | R7: =IF(COUNTIFS('Form Responses 1'!$B:$B,$B7,'Form Responses 1'!$C:$C,2025,'Form Responses 1'!$D:$D,R$2)>0,TRUE) -> TRUE | S7: =IF(COUNTIFS('Form Responses 1'!$B:$B,$B7,'Form Responses 1'!$C:$C,2025,'Form Responses 1'!$D:$D,S$2)>0,TRUE) -> TRUE | T7: =IF(COUNTIFS('Form Responses 1'!$B:$B,$B7,'Form Responses 1'!$C:$C,2025,'Form Responses 1'!$D:$D,T$2)>0,TRUE) -> TRUE | U7: =IF(COUNTIFS('Form Responses 1'!$B:$B,$B7,'Form Responses 1'!$C:$C,2025,'Form Responses 1'!$D:$D,U$2)>0,TRUE) -> TRUE | V7: =IF(COUNTIFS('Form Responses 1'!$B:$B,$B7,'Form Responses 1'!$C:$C,2025,'Form Responses 1'!$D:$D,V$2)>0,TRUE) -> TRUE | W7: =IF(COUNTIFS('Form Responses 1'!$B:$B,$B7,'Form Responses 1'!$C:$C,2025,'Form Responses 1'!$D:$D,W$2)>0,TRUE) -> TRUE | X7: =IF(COUNTIFS('Form Responses 1'!$B:$B,$B7,'Form Responses 1'!$C:$C,2025,'Form Responses 1'!$D:$D,X$2)>0,TRUE) -> TRUE | ... AF7: =IF(COUNTIFS('Form Responses 1'!$B:$B,$B7,'Form Responses 1'!$C:$C,2025,'Form Responses 1'!$D:$D,AF$2)>0,TRUE) -> TRUE | AG7: =IF(COUNTIFS('Form Responses 1'!$B:$B,$B7,'Form Responses 1'!$C:$C,2026,'Form Responses 1'!$D:$D,AG$2)>0,TRUE) -> FALSE | AH7: =IF(COUNTIFS('Form Responses 1'!$B:$B,$B7,'Form Responses 1'!$C:$C,2026,'Form Responses 1'!$D:$D,AH$2)>0,TRUE) -> FALSE | AI7: =IF(COUNTIFS('Form Responses 1'!$B:$B,$B7,'Form Responses 1'!$C:$C,2026,'Form Responses 1'!$D:$D,AI$2)>0,TRUE) -> FALSE | AJ7: =IF(COUNTIFS('Form Responses 1'!$B:$B,$B7,'Form Responses 1'!$C:$C,2026,'Form Responses 1'!$D:$D,AJ$2)>0,TRUE) -> FALSE | AK7: =IF(COUNTIFS('Form Responses 1'!$B:$B,$B7,'Form Responses 1'!$C:$C,2026,'Form Responses 1'!$D:$D,AK$2)>0,TRUE) -> FALSE | AL7: =IF(COUNTIFS('Form Responses 1'!$B:$B,$B7,'Form Responses 1'!$C:$C,2026,'Form Responses 1'!$D:$D,AL$2)>0,TRUE) -> FALSE | AM7: =IF(COUNTIFS('Form Responses 1'!$B:$B,$B7,'Form Responses 1'!$C:$C,2026,'Form Responses 1'!$D:$D,AM$2)>0,TRUE) -> FALSE | AN7: =IF(COUNTIFS('Form Responses 1'!$B:$B,$B7,'Form Responses 1'!$C:$C,2026,'Form Responses 1'!$D:$D,AN$2)>0,TRUE) -> FALSE | ... AU7: =IF(COUNTIFS('Form Responses 1'!$B:$B,$B7,'Form Responses 1'!$C:$C,2026,'Form Responses 1'!$D:$D,AU$2)>0,TRUE) -> FALSE
A8: 6 | B8: Dyah Makutaning Dewi | C8: =IF(COUNTIFS('Form Responses 1'!$B:$B,$B8,'Form Responses 1'!$C:$C,2024,'Form Responses 1'!$D:$D,C$2)>0,TRUE) -> TRUE | D8: =IF(COUNTIFS('Form Responses 1'!$B:$B,$B8,'Form Responses 1'!$C:$C,2024,'Form Responses 1'!$D:$D,D$2)>0,TRUE) -> TRUE | E8: =IF(COUNTIFS('Form Responses 1'!$B:$B,$B8,'Form Responses 1'!$C:$C,2024,'Form Responses 1'!$D:$D,E$2)>0,TRUE) -> TRUE | F8: =IF(COUNTIFS('Form Responses 1'!$B:$B,$B8,'Form Responses 1'!$C:$C,2024,'Form Responses 1'!$D:$D,F$2)>0,TRUE) -> TRUE | G8: =IF(COUNTIFS('Form Responses 1'!$B:$B,$B8,'Form Responses 1'!$C:$C,2024,'Form Responses 1'!$D:$D,G$2)>0,TRUE) -> TRUE | H8: =IF(COUNTIFS('Form Responses 1'!$B:$B,$B8,'Form Responses 1'!$C:$C,2024,'Form Responses 1'!$D:$D,H$2)>0,TRUE) -> TRUE | I8: =IF(COUNTIFS('Form Responses 1'!$B:$B,$B8,'Form Responses 1'!$C:$C,2024,'Form Responses 1'!$D:$D,I$2)>0,TRUE) -> TRUE | J8: =IF(COUNTIFS('Form Responses 1'!$B:$B,$B8,'Form Responses 1'!$C:$C,2024,'Form Responses 1'!$D:$D,J$2)>0,TRUE) -> TRUE | ... P8: =IF(COUNTIFS('Form Responses 1'!$B:$B,$B8,'Form Responses 1'!$C:$C,2024,'Form Responses 1'!$D:$D,P$2)>0,TRUE) -> TRUE | Q8: =IF(COUNTIFS('Form Responses 1'!$B:$B,$B8,'Form Responses 1'!$C:$C,2025,'Form Responses 1'!$D:$D,Q$2)>0,TRUE) -> TRUE | R8: =IF(COUNTIFS('Form Responses 1'!$B:$B,$B8,'Form Responses 1'!$C:$C,2025,'Form Responses 1'!$D:$D,R$2)>0,TRUE) -> TRUE | S8: =IF(COUNTIFS('Form Responses 1'!$B:$B,$B8,'Form Responses 1'!$C:$C,2025,'Form Responses 1'!$D:$D,S$2)>0,TRUE) -> TRUE | T8: =IF(COUNTIFS('Form Responses 1'!$B:$B,$B8,'Form Responses 1'!$C:$C,2025,'Form Responses 1'!$D:$D,T$2)>0,TRUE) -> TRUE | U8: =IF(COUNTIFS('Form Responses 1'!$B:$B,$B8,'Form Responses 1'!$C:$C,2025,'Form Responses 1'!$D:$D,U$2)>0,TRUE) -> TRUE | V8: =IF(COUNTIFS('Form Responses 1'!$B:$B,$B8,'Form Responses 1'!$C:$C,2025,'Form Responses 1'!$D:$D,V$2)>0,TRUE) -> TRUE | W8: =IF(COUNTIFS('Form Responses 1'!$B:$B,$B8,'Form Responses 1'!$C:$C,2025,'Form Responses 1'!$D:$D,W$2)>0,TRUE) -> TRUE | X8: =IF(COUNTIFS('Form Responses 1'!$B:$B,$B8,'Form Responses 1'!$C:$C,2025,'Form Responses 1'!$D:$D,X$2)>0,TRUE) -> TRUE | ... AF8: =IF(COUNTIFS('Form Responses 1'!$B:$B,$B8,'Form Responses 1'!$C:$C,2025,'Form Responses 1'!$D:$D,AF$2)>0,TRUE) -> TRUE | AG8: =IF(COUNTIFS('Form Responses 1'!$B:$B,$B8,'Form Responses 1'!$C:$C,2026,'Form Responses 1'!$D:$D,AG$2)>0,TRUE) -> FALSE | AH8: =IF(COUNTIFS('Form Responses 1'!$B:$B,$B8,'Form Responses 1'!$C:$C,2026,'Form Responses 1'!$D:$D,AH$2)>0,TRUE) -> FALSE | AI8: =IF(COUNTIFS('Form Responses 1'!$B:$B,$B8,'Form Responses 1'!$C:$C,2026,'Form Responses 1'!$D:$D,AI$2)>0,TRUE) -> FALSE | AJ8: =IF(COUNTIFS('Form Responses 1'!$B:$B,$B8,'Form Responses 1'!$C:$C,2026,'Form Responses 1'!$D:$D,AJ$2)>0,TRUE) -> FALSE | AK8: =IF(COUNTIFS('Form Responses 1'!$B:$B,$B8,'Form Responses 1'!$C:$C,2026,'Form Responses 1'!$D:$D,AK$2)>0,TRUE) -> FALSE | AL8: =IF(COUNTIFS('Form Responses 1'!$B:$B,$B8,'Form Responses 1'!$C:$C,2026,'Form Responses 1'!$D:$D,AL$2)>0,TRUE) -> FALSE | AM8: =IF(COUNTIFS('Form Responses 1'!$B:$B,$B8,'Form Responses 1'!$C:$C,2026,'Form Responses 1'!$D:$D,AM$2)>0,TRUE) -> FALSE | AN8: =IF(COUNTIFS('Form Responses 1'!$B:$B,$B8,'Form Responses 1'!$C:$C,2026,'Form Responses 1'!$D:$D,AN$2)>0,TRUE) -> FALSE | ... AU8: =IF(COUNTIFS('Form Responses 1'!$B:$B,$B8,'Form Responses 1'!$C:$C,2026,'Form Responses 1'!$D:$D,AU$2)>0,TRUE) -> FALSE
A9: 7 | B9: Musyafa'ah A.Md | C9: =IF(COUNTIFS('Form Responses 1'!$B:$B,$B9,'Form Responses 1'!$C:$C,2024,'Form Responses 1'!$D:$D,C$2)>0,TRUE) -> TRUE | D9: =IF(COUNTIFS('Form Responses 1'!$B:$B,$B9,'Form Responses 1'!$C:$C,2024,'Form Responses 1'!$D:$D,D$2)>0,TRUE) -> TRUE | E9: =IF(COUNTIFS('Form Responses 1'!$B:$B,$B9,'Form Responses 1'!$C:$C,2024,'Form Responses 1'!$D:$D,E$2)>0,TRUE) -> TRUE | F9: =IF(COUNTIFS('Form Responses 1'!$B:$B,$B9,'Form Responses 1'!$C:$C,2024,'Form Responses 1'!$D:$D,F$2)>0,TRUE) -> TRUE | G9: =IF(COUNTIFS('Form Responses 1'!$B:$B,$B9,'Form Responses 1'!$C:$C,2024,'Form Responses 1'!$D:$D,G$2)>0,TRUE) -> TRUE | H9: =IF(COUNTIFS('Form Responses 1'!$B:$B,$B9,'Form Responses 1'!$C:$C,2024,'Form Responses 1'!$D:$D,H$2)>0,TRUE) -> TRUE | I9: =IF(COUNTIFS('Form Responses 1'!$B:$B,$B9,'Form Responses 1'!$C:$C,2024,'Form Responses 1'!$D:$D,I$2)>0,TRUE) -> TRUE | J9: =IF(COUNTIFS('Form Responses 1'!$B:$B,$B9,'Form Responses 1'!$C:$C,2024,'Form Responses 1'!$D:$D,J$2)>0,TRUE) -> TRUE | ... P9: =IF(COUNTIFS('Form Responses 1'!$B:$B,$B9,'Form Responses 1'!$C:$C,2024,'Form Responses 1'!$D:$D,P$2)>0,TRUE) -> TRUE | Q9: =IF(COUNTIFS('Form Responses 1'!$B:$B,$B9,'Form Responses 1'!$C:$C,2025,'Form Responses 1'!$D:$D,Q$2)>0,TRUE) -> TRUE | R9: =IF(COUNTIFS('Form Responses 1'!$B:$B,$B9,'Form Responses 1'!$C:$C,2025,'Form Responses 1'!$D:$D,R$2)>0,TRUE) -> TRUE | S9: =IF(COUNTIFS('Form Responses 1'!$B:$B,$B9,'Form Responses 1'!$C:$C,2025,'Form Responses 1'!$D:$D,S$2)>0,TRUE) -> TRUE | T9: =IF(COUNTIFS('Form Responses 1'!$B:$B,$B9,'Form Responses 1'!$C:$C,2025,'Form Responses 1'!$D:$D,T$2)>0,TRUE) -> TRUE | U9: =IF(COUNTIFS('Form Responses 1'!$B:$B,$B9,'Form Responses 1'!$C:$C,2025,'Form Responses 1'!$D:$D,U$2)>0,TRUE) -> TRUE | V9: =IF(COUNTIFS('Form Responses 1'!$B:$B,$B9,'Form Responses 1'!$C:$C,2025,'Form Responses 1'!$D:$D,V$2)>0,TRUE) -> TRUE | W9: =IF(COUNTIFS('Form Responses 1'!$B:$B,$B9,'Form Responses 1'!$C:$C,2025,'Form Responses 1'!$D:$D,W$2)>0,TRUE) -> TRUE | X9: =IF(COUNTIFS('Form Responses 1'!$B:$B,$B9,'Form Responses 1'!$C:$C,2025,'Form Responses 1'!$D:$D,X$2)>0,TRUE) -> TRUE | ... AF9: =IF(COUNTIFS('Form Responses 1'!$B:$B,$B9,'Form Responses 1'!$C:$C,2025,'Form Responses 1'!$D:$D,AF$2)>0,TRUE) -> TRUE | AG9: =IF(COUNTIFS('Form Responses 1'!$B:$B,$B9,'Form Responses 1'!$C:$C,2026,'Form Responses 1'!$D:$D,AG$2)>0,TRUE) -> FALSE | AH9: =IF(COUNTIFS('Form Responses 1'!$B:$B,$B9,'Form Responses 1'!$C:$C,2026,'Form Responses 1'!$D:$D,AH$2)>0,TRUE) -> FALSE | AI9: =IF(COUNTIFS('Form Responses 1'!$B:$B,$B9,'Form Responses 1'!$C:$C,2026,'Form Responses 1'!$D:$D,AI$2)>0,TRUE) -> FALSE | AJ9: =IF(COUNTIFS('Form Responses 1'!$B:$B,$B9,'Form Responses 1'!$C:$C,2026,'Form Responses 1'!$D:$D,AJ$2)>0,TRUE) -> FALSE | AK9: =IF(COUNTIFS('Form Responses 1'!$B:$B,$B9,'Form Responses 1'!$C:$C,2026,'Form Responses 1'!$D:$D,AK$2)>0,TRUE) -> FALSE | AL9: =IF(COUNTIFS('Form Responses 1'!$B:$B,$B9,'Form Responses 1'!$C:$C,2026,'Form Responses 1'!$D:$D,AL$2)>0,TRUE) -> FALSE | AM9: =IF(COUNTIFS('Form Responses 1'!$B:$B,$B9,'Form Responses 1'!$C:$C,2026,'Form Responses 1'!$D:$D,AM$2)>0,TRUE) -> FALSE | AN9: =IF(COUNTIFS('Form Responses 1'!$B:$B,$B9,'Form Responses 1'!$C:$C,2026,'Form Responses 1'!$D:$D,AN$2)>0,TRUE) -> FALSE | ... AU9: =IF(COUNTIFS('Form Responses 1'!$B:$B,$B9,'Form Responses 1'!$C:$C,2026,'Form Responses 1'!$D:$D,AU$2)>0,TRUE) -> FALSE
A10: 8 | B10: Aris Sutikno SE | C10: =IF(COUNTIFS('Form Responses 1'!$B:$B,$B10,'Form Responses 1'!$C:$C,2024,'Form Responses 1'!$D:$D,C$2)>0,TRUE) -> TRUE | D10: =IF(COUNTIFS('Form Responses 1'!$B:$B,$B10,'Form Responses 1'!$C:$C,2024,'Form Responses 1'!$D:$D,D$2)>0,TRUE) -> TRUE | E10: =IF(COUNTIFS('Form Responses 1'!$B:$B,$B10,'Form Responses 1'!$C:$C,2024,'Form Responses 1'!$D:$D,E$2)>0,TRUE) -> TRUE | F10: =IF(COUNTIFS('Form Responses 1'!$B:$B,$B10,'Form Responses 1'!$C:$C,2024,'Form Responses 1'!$D:$D,F$2)>0,TRUE) -> TRUE | G10: =IF(COUNTIFS('Form Responses 1'!$B:$B,$B10,'Form Responses 1'!$C:$C,2024,'Form Responses 1'!$D:$D,G$2)>0,TRUE) -> TRUE | H10: =IF(COUNTIFS('Form Responses 1'!$B:$B,$B10,'Form Responses 1'!$C:$C,2024,'Form Responses 1'!$D:$D,H$2)>0,TRUE) -> TRUE | I10: =IF(COUNTIFS('Form Responses 1'!$B:$B,$B10,'Form Responses 1'!$C:$C,2024,'Form Responses 1'!$D:$D,I$2)>0,TRUE) -> TRUE | J10: =IF(COUNTIFS('Form Responses 1'!$B:$B,$B10,'Form Responses 1'!$C:$C,2024,'Form Responses 1'!$D:$D,J$2)>0,TRUE) -> TRUE | ... P10: =IF(COUNTIFS('Form Responses 1'!$B:$B,$B10,'Form Responses 1'!$C:$C,2024,'Form Responses 1'!$D:$D,P$2)>0,TRUE) -> TRUE | Q10: =IF(COUNTIFS('Form Responses 1'!$B:$B,$B10,'Form Responses 1'!$C:$C,2025,'Form Responses 1'!$D:$D,Q$2)>0,TRUE) -> TRUE | R10: =IF(COUNTIFS('Form Responses 1'!$B:$B,$B10,'Form Responses 1'!$C:$C,2025,'Form Responses 1'!$D:$D,R$2)>0,TRUE) -> TRUE | S10: =IF(COUNTIFS('Form Responses 1'!$B:$B,$B10,'Form Responses 1'!$C:$C,2025,'Form Responses 1'!$D:$D,S$2)>0,TRUE) -> TRUE | T10: =IF(COUNTIFS('Form Responses 1'!$B:$B,$B10,'Form Responses 1'!$C:$C,2025,'Form Responses 1'!$D:$D,T$2)>0,TRUE) -> TRUE | U10: =IF(COUNTIFS('Form Responses 1'!$B:$B,$B10,'Form Responses 1'!$C:$C,2025,'Form Responses 1'!$D:$D,U$2)>0,TRUE) -> TRUE | V10: =IF(COUNTIFS('Form Responses 1'!$B:$B,$B10,'Form Responses 1'!$C:$C,2025,'Form Responses 1'!$D:$D,V$2)>0,TRUE) -> TRUE | W10: =IF(COUNTIFS('Form Responses 1'!$B:$B,$B10,'Form Responses 1'!$C:$C,2025,'Form Responses 1'!$D:$D,W$2)>0,TRUE) -> TRUE | X10: =IF(COUNTIFS('Form Responses 1'!$B:$B,$B10,'Form Responses 1'!$C:$C,2025,'Form Responses 1'!$D:$D,X$2)>0,TRUE) -> TRUE | ... AF10: =IF(COUNTIFS('Form Responses 1'!$B:$B,$B10,'Form Responses 1'!$C:$C,2025,'Form Responses 1'!$D:$D,AF$2)>0,TRUE) -> TRUE | AG10: =IF(COUNTIFS('Form Responses 1'!$B:$B,$B10,'Form Responses 1'!$C:$C,2026,'Form Responses 1'!$D:$D,AG$2)>0,TRUE) -> FALSE | AH10: =IF(COUNTIFS('Form Responses 1'!$B:$B,$B10,'Form Responses 1'!$C:$C,2026,'Form Responses 1'!$D:$D,AH$2)>0,TRUE) -> FALSE | AI10: =IF(COUNTIFS('Form Responses 1'!$B:$B,$B10,'Form Responses 1'!$C:$C,2026,'Form Responses 1'!$D:$D,AI$2)>0,TRUE) -> FALSE | AJ10: =IF(COUNTIFS('Form Responses 1'!$B:$B,$B10,'Form Responses 1'!$C:$C,2026,'Form Responses 1'!$D:$D,AJ$2)>0,TRUE) -> FALSE | AK10: =IF(COUNTIFS('Form Responses 1'!$B:$B,$B10,'Form Responses 1'!$C:$C,2026,'Form Responses 1'!$D:$D,AK$2)>0,TRUE) -> FALSE | AL10: =IF(COUNTIFS('Form Responses 1'!$B:$B,$B10,'Form Responses 1'!$C:$C,2026,'Form Responses 1'!$D:$D,AL$2)>0,TRUE) -> FALSE | AM10: =IF(COUNTIFS('Form Responses 1'!$B:$B,$B10,'Form Responses 1'!$C:$C,2026,'Form Responses 1'!$D:$D,AM$2)>0,TRUE) -> FALSE | AN10: =IF(COUNTIFS('Form Responses 1'!$B:$B,$B10,'Form Responses 1'!$C:$C,2026,'Form Responses 1'!$D:$D,AN$2)>0,TRUE) -> FALSE | ... AU10: =IF(COUNTIFS('Form Responses 1'!$B:$B,$B10,'Form Responses 1'!$C:$C,2026,'Form Responses 1'!$D:$D,AU$2)>0,TRUE) -> FALSE
A11: 9 | B11: Abdul Khalim | C11: =IF(COUNTIFS('Form Responses 1'!$B:$B,$B11,'Form Responses 1'!$C:$C,2024,'Form Responses 1'!$D:$D,C$2)>0,TRUE) -> TRUE | D11: =IF(COUNTIFS('Form Responses 1'!$B:$B,$B11,'Form Responses 1'!$C:$C,2024,'Form Responses 1'!$D:$D,D$2)>0,TRUE) -> TRUE | E11: =IF(COUNTIFS('Form Responses 1'!$B:$B,$B11,'Form Responses 1'!$C:$C,2024,'Form Responses 1'!$D:$D,E$2)>0,TRUE) -> TRUE | F11: =IF(COUNTIFS('Form Responses 1'!$B:$B,$B11,'Form Responses 1'!$C:$C,2024,'Form Responses 1'!$D:$D,F$2)>0,TRUE) -> TRUE | G11: =IF(COUNTIFS('Form Responses 1'!$B:$B,$B11,'Form Responses 1'!$C:$C,2024,'Form Responses 1'!$D:$D,G$2)>0,TRUE) -> TRUE | H11: =IF(COUNTIFS('Form Responses 1'!$B:$B,$B11,'Form Responses 1'!$C:$C,2024,'Form Responses 1'!$D:$D,H$2)>0,TRUE) -> TRUE | I11: =IF(COUNTIFS('Form Responses 1'!$B:$B,$B11,'Form Responses 1'!$C:$C,2024,'Form Responses 1'!$D:$D,I$2)>0,TRUE) -> TRUE | J11: =IF(COUNTIFS('Form Responses 1'!$B:$B,$B11,'Form Responses 1'!$C:$C,2024,'Form Responses 1'!$D:$D,J$2)>0,TRUE) -> TRUE | ... P11: =IF(COUNTIFS('Form Responses 1'!$B:$B,$B11,'Form Responses 1'!$C:$C,2024,'Form Responses 1'!$D:$D,P$2)>0,TRUE) -> TRUE | Q11: =IF(COUNTIFS('Form Responses 1'!$B:$B,$B11,'Form Responses 1'!$C:$C,2025,'Form Responses 1'!$D:$D,Q$2)>0,TRUE) -> TRUE | R11: =IF(COUNTIFS('Form Responses 1'!$B:$B,$B11,'Form Responses 1'!$C:$C,2025,'Form Responses 1'!$D:$D,R$2)>0,TRUE) -> TRUE | S11: =IF(COUNTIFS('Form Responses 1'!$B:$B,$B11,'Form Responses 1'!$C:$C,2025,'Form Responses 1'!$D:$D,S$2)>0,TRUE) -> TRUE | T11: =IF(COUNTIFS('Form Responses 1'!$B:$B,$B11,'Form Responses 1'!$C:$C,2025,'Form Responses 1'!$D:$D,T$2)>0,TRUE) -> TRUE | U11: =IF(COUNTIFS('Form Responses 1'!$B:$B,$B11,'Form Responses 1'!$C:$C,2025,'Form Responses 1'!$D:$D,U$2)>0,TRUE) -> TRUE | V11: =IF(COUNTIFS('Form Responses 1'!$B:$B,$B11,'Form Responses 1'!$C:$C,2025,'Form Responses 1'!$D:$D,V$2)>0,TRUE) -> TRUE | W11: =IF(COUNTIFS('Form Responses 1'!$B:$B,$B11,'Form Responses 1'!$C:$C,2025,'Form Responses 1'!$D:$D,W$2)>0,TRUE) -> TRUE | X11: =IF(COUNTIFS('Form Responses 1'!$B:$B,$B11,'Form Responses 1'!$C:$C,2025,'Form Responses 1'!$D:$D,X$2)>0,TRUE) -> TRUE | ... AF11: =IF(COUNTIFS('Form Responses 1'!$B:$B,$B11,'Form Responses 1'!$C:$C,2025,'Form Responses 1'!$D:$D,AF$2)>0,TRUE) -> TRUE | AG11: =IF(COUNTIFS('Form Responses 1'!$B:$B,$B11,'Form Responses 1'!$C:$C,2026,'Form Responses 1'!$D:$D,AG$2)>0,TRUE) -> FALSE | AH11: =IF(COUNTIFS('Form Responses 1'!$B:$B,$B11,'Form Responses 1'!$C:$C,2026,'Form Responses 1'!$D:$D,AH$2)>0,TRUE) -> FALSE | AI11: =IF(COUNTIFS('Form Responses 1'!$B:$B,$B11,'Form Responses 1'!$C:$C,2026,'Form Responses 1'!$D:$D,AI$2)>0,TRUE) -> FALSE | AJ11: =IF(COUNTIFS('Form Responses 1'!$B:$B,$B11,'Form Responses 1'!$C:$C,2026,'Form Responses 1'!$D:$D,AJ$2)>0,TRUE) -> FALSE | AK11: =IF(COUNTIFS('Form Responses 1'!$B:$B,$B11,'Form Responses 1'!$C:$C,2026,'Form Responses 1'!$D:$D,AK$2)>0,TRUE) -> FALSE | AL11: =IF(COUNTIFS('Form Responses 1'!$B:$B,$B11,'Form Responses 1'!$C:$C,2026,'Form Responses 1'!$D:$D,AL$2)>0,TRUE) -> FALSE | AM11: =IF(COUNTIFS('Form Responses 1'!$B:$B,$B11,'Form Responses 1'!$C:$C,2026,'Form Responses 1'!$D:$D,AM$2)>0,TRUE) -> FALSE | AN11: =IF(COUNTIFS('Form Responses 1'!$B:$B,$B11,'Form Responses 1'!$C:$C,2026,'Form Responses 1'!$D:$D,AN$2)>0,TRUE) -> FALSE | ... AU11: =IF(COUNTIFS('Form Responses 1'!$B:$B,$B11,'Form Responses 1'!$C:$C,2026,'Form Responses 1'!$D:$D,AU$2)>0,TRUE) -> FALSE
A12: 10 | B12: M Abdul Muhshi | C12: =IF(COUNTIFS('Form Responses 1'!$B:$B,$B12,'Form Responses 1'!$C:$C,2024,'Form Responses 1'!$D:$D,C$2)>0,TRUE) -> FALSE | D12: =IF(COUNTIFS('Form Responses 1'!$B:$B,$B12,'Form Responses 1'!$C:$C,2024,'Form Responses 1'!$D:$D,D$2)>0,TRUE) -> TRUE | E12: =IF(COUNTIFS('Form Responses 1'!$B:$B,$B12,'Form Responses 1'!$C:$C,2024,'Form Responses 1'!$D:$D,E$2)>0,TRUE) -> TRUE | F12: =IF(COUNTIFS('Form Responses 1'!$B:$B,$B12,'Form Responses 1'!$C:$C,2024,'Form Responses 1'!$D:$D,F$2)>0,TRUE) -> TRUE | G12: =IF(COUNTIFS('Form Responses 1'!$B:$B,$B12,'Form Responses 1'!$C:$C,2024,'Form Responses 1'!$D:$D,G$2)>0,TRUE) -> TRUE | H12: =IF(COUNTIFS('Form Responses 1'!$B:$B,$B12,'Form Responses 1'!$C:$C,2024,'Form Responses 1'!$D:$D,H$2)>0,TRUE) -> TRUE | I12: =IF(COUNTIFS('Form Responses 1'!$B:$B,$B12,'Form Responses 1'!$C:$C,2024,'Form Responses 1'!$D:$D,I$2)>0,TRUE) -> TRUE | J12: =IF(COUNTIFS('Form Responses 1'!$B:$B,$B12,'Form Responses 1'!$C:$C,2024,'Form Responses 1'!$D:$D,J$2)>0,TRUE) -> TRUE | ... P12: =IF(COUNTIFS('Form Responses 1'!$B:$B,$B12,'Form Responses 1'!$C:$C,2024,'Form Responses 1'!$D:$D,P$2)>0,TRUE) -> TRUE | Q12: =IF(COUNTIFS('Form Responses 1'!$B:$B,$B12,'Form Responses 1'!$C:$C,2025,'Form Responses 1'!$D:$D,Q$2)>0,TRUE) -> TRUE | R12: =IF(COUNTIFS('Form Responses 1'!$B:$B,$B12,'Form Responses 1'!$C:$C,2025,'Form Responses 1'!$D:$D,R$2)>0,TRUE) -> TRUE | S12: =IF(COUNTIFS('Form Responses 1'!$B:$B,$B12,'Form Responses 1'!$C:$C,2025,'Form Responses 1'!$D:$D,S$2)>0,TRUE) -> TRUE | T12: =IF(COUNTIFS('Form Responses 1'!$B:$B,$B12,'Form Responses 1'!$C:$C,2025,'Form Responses 1'!$D:$D,T$2)>0,TRUE) -> TRUE | U12: =IF(COUNTIFS('Form Responses 1'!$B:$B,$B12,'Form Responses 1'!$C:$C,2025,'Form Responses 1'!$D:$D,U$2)>0,TRUE) -> TRUE | V12: =IF(COUNTIFS('Form Responses 1'!$B:$B,$B12,'Form Responses 1'!$C:$C,2025,'Form Responses 1'!$D:$D,V$2)>0,TRUE) -> TRUE | W12: =IF(COUNTIFS('Form Responses 1'!$B:$B,$B12,'Form Responses 1'!$C:$C,2025,'Form Responses 1'!$D:$D,W$2)>0,TRUE) -> TRUE | X12: =IF(COUNTIFS('Form Responses 1'!$B:$B,$B12,'Form Responses 1'!$C:$C,2025,'Form Responses 1'!$D:$D,X$2)>0,TRUE) -> TRUE | ... AF12: =IF(COUNTIFS('Form Responses 1'!$B:$B,$B12,'Form Responses 1'!$C:$C,2025,'Form Responses 1'!$D:$D,AF$2)>0,TRUE) -> TRUE | AG12: =IF(COUNTIFS('Form Responses 1'!$B:$B,$B12,'Form Responses 1'!$C:$C,2026,'Form Responses 1'!$D:$D,AG$2)>0,TRUE) -> FALSE | AH12: =IF(COUNTIFS('Form Responses 1'!$B:$B,$B12,'Form Responses 1'!$C:$C,2026,'Form Responses 1'!$D:$D,AH$2)>0,TRUE) -> FALSE | AI12: =IF(COUNTIFS('Form Responses 1'!$B:$B,$B12,'Form Responses 1'!$C:$C,2026,'Form Responses 1'!$D:$D,AI$2)>0,TRUE) -> FALSE | AJ12: =IF(COUNTIFS('Form Responses 1'!$B:$B,$B12,'Form Responses 1'!$C:$C,2026,'Form Responses 1'!$D:$D,AJ$2)>0,TRUE) -> FALSE | AK12: =IF(COUNTIFS('Form Responses 1'!$B:$B,$B12,'Form Responses 1'!$C:$C,2026,'Form Responses 1'!$D:$D,AK$2)>0,TRUE) -> FALSE | AL12: =IF(COUNTIFS('Form Responses 1'!$B:$B,$B12,'Form Responses 1'!$C:$C,2026,'Form Responses 1'!$D:$D,AL$2)>0,TRUE) -> FALSE | AM12: =IF(COUNTIFS('Form Responses 1'!$B:$B,$B12,'Form Responses 1'!$C:$C,2026,'Form Responses 1'!$D:$D,AM$2)>0,TRUE) -> FALSE | AN12: =IF(COUNTIFS('Form Responses 1'!$B:$B,$B12,'Form Responses 1'!$C:$C,2026,'Form Responses 1'!$D:$D,AN$2)>0,TRUE) -> FALSE | ... AU12: =IF(COUNTIFS('Form Responses 1'!$B:$B,$B12,'Form Responses 1'!$C:$C,2026,'Form Responses 1'!$D:$D,AU$2)>0,TRUE) -> FALSE
A13: 11 | B13: Herwastuti Dwi Oktaviani A.Md. | C13: =IF(COUNTIFS('Form Responses 1'!$B:$B,$B13,'Form Responses 1'!$C:$C,2024,'Form Responses 1'!$D:$D,C$2)>0,TRUE) -> FALSE | D13: =IF(COUNTIFS('Form Responses 1'!$B:$B,$B13,'Form Responses 1'!$C:$C,2024,'Form Responses 1'!$D:$D,D$2)>0,TRUE) -> TRUE | E13: =IF(COUNTIFS('Form Responses 1'!$B:$B,$B13,'Form Responses 1'!$C:$C,2024,'Form Responses 1'!$D:$D,E$2)>0,TRUE) -> TRUE | F13: =IF(COUNTIFS('Form Responses 1'!$B:$B,$B13,'Form Responses 1'!$C:$C,2024,'Form Responses 1'!$D:$D,F$2)>0,TRUE) -> TRUE | G13: =IF(COUNTIFS('Form Responses 1'!$B:$B,$B13,'Form Responses 1'!$C:$C,2024,'Form Responses 1'!$D:$D,G$2)>0,TRUE) -> TRUE | H13: =IF(COUNTIFS('Form Responses 1'!$B:$B,$B13,'Form Responses 1'!$C:$C,2024,'Form Responses 1'!$D:$D,H$2)>0,TRUE) -> TRUE | I13: =IF(COUNTIFS('Form Responses 1'!$B:$B,$B13,'Form Responses 1'!$C:$C,2024,'Form Responses 1'!$D:$D,I$2)>0,TRUE) -> TRUE | J13: =IF(COUNTIFS('Form Responses 1'!$B:$B,$B13,'Form Responses 1'!$C:$C,2024,'Form Responses 1'!$D:$D,J$2)>0,TRUE) -> TRUE | ... P13: =IF(COUNTIFS('Form Responses 1'!$B:$B,$B13,'Form Responses 1'!$C:$C,2024,'Form Responses 1'!$D:$D,P$2)>0,TRUE) -> FALSE | Q13: =IF(COUNTIFS('Form Responses 1'!$B:$B,$B13,'Form Responses 1'!$C:$C,2025,'Form Responses 1'!$D:$D,Q$2)>0,TRUE) -> TRUE | R13: =IF(COUNTIFS('Form Responses 1'!$B:$B,$B13,'Form Responses 1'!$C:$C,2025,'Form Responses 1'!$D:$D,R$2)>0,TRUE) -> TRUE | S13: =IF(COUNTIFS('Form Responses 1'!$B:$B,$B13,'Form Responses 1'!$C:$C,2025,'Form Responses 1'!$D:$D,S$2)>0,TRUE) -> TRUE | T13: =IF(COUNTIFS('Form Responses 1'!$B:$B,$B13,'Form Responses 1'!$C:$C,2025,'Form Responses 1'!$D:$D,T$2)>0,TRUE) -> TRUE | U13: =IF(COUNTIFS('Form Responses 1'!$B:$B,$B13,'Form Responses 1'!$C:$C,2025,'Form Responses 1'!$D:$D,U$2)>0,TRUE) -> TRUE | V13: =IF(COUNTIFS('Form Responses 1'!$B:$B,$B13,'Form Responses 1'!$C:$C,2025,'Form Responses 1'!$D:$D,V$2)>0,TRUE) -> TRUE | W13: =IF(COUNTIFS('Form Responses 1'!$B:$B,$B13,'Form Responses 1'!$C:$C,2025,'Form Responses 1'!$D:$D,W$2)>0,TRUE) -> TRUE | X13: =IF(COUNTIFS('Form Responses 1'!$B:$B,$B13,'Form Responses 1'!$C:$C,2025,'Form Responses 1'!$D:$D,X$2)>0,TRUE) -> TRUE | ... AF13: =IF(COUNTIFS('Form Responses 1'!$B:$B,$B13,'Form Responses 1'!$C:$C,2025,'Form Responses 1'!$D:$D,AF$2)>0,TRUE) -> TRUE | AG13: =IF(COUNTIFS('Form Responses 1'!$B:$B,$B13,'Form Responses 1'!$C:$C,2026,'Form Responses 1'!$D:$D,AG$2)>0,TRUE) -> FALSE | AH13: =IF(COUNTIFS('Form Responses 1'!$B:$B,$B13,'Form Responses 1'!$C:$C,2026,'Form Responses 1'!$D:$D,AH$2)>0,TRUE) -> FALSE | AI13: =IF(COUNTIFS('Form Responses 1'!$B:$B,$B13,'Form Responses 1'!$C:$C,2026,'Form Responses 1'!$D:$D,AI$2)>0,TRUE) -> FALSE | AJ13: =IF(COUNTIFS('Form Responses 1'!$B:$B,$B13,'Form Responses 1'!$C:$C,2026,'Form Responses 1'!$D:$D,AJ$2)>0,TRUE) -> FALSE | AK13: =IF(COUNTIFS('Form Responses 1'!$B:$B,$B13,'Form Responses 1'!$C:$C,2026,'Form Responses 1'!$D:$D,AK$2)>0,TRUE) -> FALSE | AL13: =IF(COUNTIFS('Form Responses 1'!$B:$B,$B13,'Form Responses 1'!$C:$C,2026,'Form Responses 1'!$D:$D,AL$2)>0,TRUE) -> FALSE | AM13: =IF(COUNTIFS('Form Responses 1'!$B:$B,$B13,'Form Responses 1'!$C:$C,2026,'Form Responses 1'!$D:$D,AM$2)>0,TRUE) -> FALSE | AN13: =IF(COUNTIFS('Form Responses 1'!$B:$B,$B13,'Form Responses 1'!$C:$C,2026,'Form Responses 1'!$D:$D,AN$2)>0,TRUE) -> FALSE | ... AU13: =IF(COUNTIFS('Form Responses 1'!$B:$B,$B13,'Form Responses 1'!$C:$C,2026,'Form Responses 1'!$D:$D,AU$2)>0,TRUE) -> FALSE
A14: 12 | B14: Khusnul Khotimah A.Md | C14: =IF(COUNTIFS('Form Responses 1'!$B:$B,$B14,'Form Responses 1'!$C:$C,2024,'Form Responses 1'!$D:$D,C$2)>0,TRUE) -> FALSE | D14: =IF(COUNTIFS('Form Responses 1'!$B:$B,$B14,'Form Responses 1'!$C:$C,2024,'Form Responses 1'!$D:$D,D$2)>0,TRUE) -> TRUE | E14: =IF(COUNTIFS('Form Responses 1'!$B:$B,$B14,'Form Responses 1'!$C:$C,2024,'Form Responses 1'!$D:$D,E$2)>0,TRUE) -> TRUE | F14: =IF(COUNTIFS('Form Responses 1'!$B:$B,$B14,'Form Responses 1'!$C:$C,2024,'Form Responses 1'!$D:$D,F$2)>0,TRUE) -> TRUE | G14: =IF(COUNTIFS('Form Responses 1'!$B:$B,$B14,'Form Responses 1'!$C:$C,2024,'Form Responses 1'!$D:$D,G$2)>0,TRUE) -> TRUE | H14: =IF(COUNTIFS('Form Responses 1'!$B:$B,$B14,'Form Responses 1'!$C:$C,2024,'Form Responses 1'!$D:$D,H$2)>0,TRUE) -> TRUE | I14: =IF(COUNTIFS('Form Responses 1'!$B:$B,$B14,'Form Responses 1'!$C:$C,2024,'Form Responses 1'!$D:$D,I$2)>0,TRUE) -> TRUE | J14: =IF(COUNTIFS('Form Responses 1'!$B:$B,$B14,'Form Responses 1'!$C:$C,2024,'Form Responses 1'!$D:$D,J$2)>0,TRUE) -> TRUE | ... P14: =IF(COUNTIFS('Form Responses 1'!$B:$B,$B14,'Form Responses 1'!$C:$C,2024,'Form Responses 1'!$D:$D,P$2)>0,TRUE) -> TRUE | Q14: =IF(COUNTIFS('Form Responses 1'!$B:$B,$B14,'Form Responses 1'!$C:$C,2025,'Form Responses 1'!$D:$D,Q$2)>0,TRUE) -> TRUE | R14: =IF(COUNTIFS('Form Responses 1'!$B:$B,$B14,'Form Responses 1'!$C:$C,2025,'Form Responses 1'!$D:$D,R$2)>0,TRUE) -> TRUE | S14: =IF(COUNTIFS('Form Responses 1'!$B:$B,$B14,'Form Responses 1'!$C:$C,2025,'Form Responses 1'!$D:$D,S$2)>0,TRUE) -> TRUE | T14: =IF(COUNTIFS('Form Responses 1'!$B:$B,$B14,'Form Responses 1'!$C:$C,2025,'Form Responses 1'!$D:$D,T$2)>0,TRUE) -> TRUE | U14: =IF(COUNTIFS('Form Responses 1'!$B:$B,$B14,'Form Responses 1'!$C:$C,2025,'Form Responses 1'!$D:$D,U$2)>0,TRUE) -> TRUE | V14: =IF(COUNTIFS('Form Responses 1'!$B:$B,$B14,'Form Responses 1'!$C:$C,2025,'Form Responses 1'!$D:$D,V$2)>0,TRUE) -> TRUE | W14: =IF(COUNTIFS('Form Responses 1'!$B:$B,$B14,'Form Responses 1'!$C:$C,2025,'Form Responses 1'!$D:$D,W$2)>0,TRUE) -> TRUE | X14: =IF(COUNTIFS('Form Responses 1'!$B:$B,$B14,'Form Responses 1'!$C:$C,2025,'Form Responses 1'!$D:$D,X$2)>0,TRUE) -> TRUE | ... AF14: =IF(COUNTIFS('Form Responses 1'!$B:$B,$B14,'Form Responses 1'!$C:$C,2025,'Form Responses 1'!$D:$D,AF$2)>0,TRUE) -> TRUE | AG14: =IF(COUNTIFS('Form Responses 1'!$B:$B,$B14,'Form Responses 1'!$C:$C,2026,'Form Responses 1'!$D:$D,AG$2)>0,TRUE) -> FALSE | AH14: =IF(COUNTIFS('Form Responses 1'!$B:$B,$B14,'Form Responses 1'!$C:$C,2026,'Form Responses 1'!$D:$D,AH$2)>0,TRUE) -> FALSE | AI14: =IF(COUNTIFS('Form Responses 1'!$B:$B,$B14,'Form Responses 1'!$C:$C,2026,'Form Responses 1'!$D:$D,AI$2)>0,TRUE) -> FALSE | AJ14: =IF(COUNTIFS('Form Responses 1'!$B:$B,$B14,'Form Responses 1'!$C:$C,2026,'Form Responses 1'!$D:$D,AJ$2)>0,TRUE) -> FALSE | AK14: =IF(COUNTIFS('Form Responses 1'!$B:$B,$B14,'Form Responses 1'!$C:$C,2026,'Form Responses 1'!$D:$D,AK$2)>0,TRUE) -> FALSE | AL14: =IF(COUNTIFS('Form Responses 1'!$B:$B,$B14,'Form Responses 1'!$C:$C,2026,'Form Responses 1'!$D:$D,AL$2)>0,TRUE) -> FALSE | AM14: =IF(COUNTIFS('Form Responses 1'!$B:$B,$B14,'Form Responses 1'!$C:$C,2026,'Form Responses 1'!$D:$D,AM$2)>0,TRUE) -> FALSE | AN14: =IF(COUNTIFS('Form Responses 1'!$B:$B,$B14,'Form Responses 1'!$C:$C,2026,'Form Responses 1'!$D:$D,AN$2)>0,TRUE) -> FALSE | ... AU14: =IF(COUNTIFS('Form Responses 1'!$B:$B,$B14,'Form Responses 1'!$C:$C,2026,'Form Responses 1'!$D:$D,AU$2)>0,TRUE) -> FALSE
A15: 13 | B15: Aji Wahyu Ramadhani SST, M.Si | C15: =IF(COUNTIFS('Form Responses 1'!$B:$B,$B15,'Form Responses 1'!$C:$C,2024,'Form Responses 1'!$D:$D,C$2)>0,TRUE) -> TRUE | D15: =IF(COUNTIFS('Form Responses 1'!$B:$B,$B15,'Form Responses 1'!$C:$C,2024,'Form Responses 1'!$D:$D,D$2)>0,TRUE) -> TRUE | E15: =IF(COUNTIFS('Form Responses 1'!$B:$B,$B15,'Form Responses 1'!$C:$C,2024,'Form Responses 1'!$D:$D,E$2)>0,TRUE) -> TRUE | F15: =IF(COUNTIFS('Form Responses 1'!$B:$B,$B15,'Form Responses 1'!$C:$C,2024,'Form Responses 1'!$D:$D,F$2)>0,TRUE) -> TRUE | G15: =IF(COUNTIFS('Form Responses 1'!$B:$B,$B15,'Form Responses 1'!$C:$C,2024,'Form Responses 1'!$D:$D,G$2)>0,TRUE) -> TRUE | H15: =IF(COUNTIFS('Form Responses 1'!$B:$B,$B15,'Form Responses 1'!$C:$C,2024,'Form Responses 1'!$D:$D,H$2)>0,TRUE) -> TRUE | I15: =IF(COUNTIFS('Form Responses 1'!$B:$B,$B15,'Form Responses 1'!$C:$C,2024,'Form Responses 1'!$D:$D,I$2)>0,TRUE) -> TRUE | J15: =IF(COUNTIFS('Form Responses 1'!$B:$B,$B15,'Form Responses 1'!$C:$C,2024,'Form Responses 1'!$D:$D,J$2)>0,TRUE) -> TRUE | ... P15: =IF(COUNTIFS('Form Responses 1'!$B:$B,$B15,'Form Responses 1'!$C:$C,2024,'Form Responses 1'!$D:$D,P$2)>0,TRUE) -> FALSE | Q15: =IF(COUNTIFS('Form Responses 1'!$B:$B,$B15,'Form Responses 1'!$C:$C,2025,'Form Responses 1'!$D:$D,Q$2)>0,TRUE) -> TRUE | R15: =IF(COUNTIFS('Form Responses 1'!$B:$B,$B15,'Form Responses 1'!$C:$C,2025,'Form Responses 1'!$D:$D,R$2)>0,TRUE) -> TRUE | S15: =IF(COUNTIFS('Form Responses 1'!$B:$B,$B15,'Form Responses 1'!$C:$C,2025,'Form Responses 1'!$D:$D,S$2)>0,TRUE) -> TRUE | T15: =IF(COUNTIFS('Form Responses 1'!$B:$B,$B15,'Form Responses 1'!$C:$C,2025,'Form Responses 1'!$D:$D,T$2)>0,TRUE) -> TRUE | U15: =IF(COUNTIFS('Form Responses 1'!$B:$B,$B15,'Form Responses 1'!$C:$C,2025,'Form Responses 1'!$D:$D,U$2)>0,TRUE) -> TRUE | V15: =IF(COUNTIFS('Form Responses 1'!$B:$B,$B15,'Form Responses 1'!$C:$C,2025,'Form Responses 1'!$D:$D,V$2)>0,TRUE) -> TRUE | W15: =IF(COUNTIFS('Form Responses 1'!$B:$B,$B15,'Form Responses 1'!$C:$C,2025,'Form Responses 1'!$D:$D,W$2)>0,TRUE) -> TRUE | X15: =IF(COUNTIFS('Form Responses 1'!$B:$B,$B15,'Form Responses 1'!$C:$C,2025,'Form Responses 1'!$D:$D,X$2)>0,TRUE) -> TRUE | ... AF15: =IF(COUNTIFS('Form Responses 1'!$B:$B,$B15,'Form Responses 1'!$C:$C,2025,'Form Responses 1'!$D:$D,AF$2)>0,TRUE) -> TRUE | AG15: =IF(COUNTIFS('Form Responses 1'!$B:$B,$B15,'Form Responses 1'!$C:$C,2026,'Form Responses 1'!$D:$D,AG$2)>0,TRUE) -> FALSE | AH15: =IF(COUNTIFS('Form Responses 1'!$B:$B,$B15,'Form Responses 1'!$C:$C,2026,'Form Responses 1'!$D:$D,AH$2)>0,TRUE) -> FALSE | AI15: =IF(COUNTIFS('Form Responses 1'!$B:$B,$B15,'Form Responses 1'!$C:$C,2026,'Form Responses 1'!$D:$D,AI$2)>0,TRUE) -> FALSE | AJ15: =IF(COUNTIFS('Form Responses 1'!$B:$B,$B15,'Form Responses 1'!$C:$C,2026,'Form Responses 1'!$D:$D,AJ$2)>0,TRUE) -> FALSE | AK15: =IF(COUNTIFS('Form Responses 1'!$B:$B,$B15,'Form Responses 1'!$C:$C,2026,'Form Responses 1'!$D:$D,AK$2)>0,TRUE) -> FALSE | AL15: =IF(COUNTIFS('Form Responses 1'!$B:$B,$B15,'Form Responses 1'!$C:$C,2026,'Form Responses 1'!$D:$D,AL$2)>0,TRUE) -> FALSE | AM15: =IF(COUNTIFS('Form Responses 1'!$B:$B,$B15,'Form Responses 1'!$C:$C,2026,'Form Responses 1'!$D:$D,AM$2)>0,TRUE) -> FALSE | AN15: =IF(COUNTIFS('Form Responses 1'!$B:$B,$B15,'Form Responses 1'!$C:$C,2026,'Form Responses 1'!$D:$D,AN$2)>0,TRUE) -> FALSE | ... AU15: =IF(COUNTIFS('Form Responses 1'!$B:$B,$B15,'Form Responses 1'!$C:$C,2026,'Form Responses 1'!$D:$D,AU$2)>0,TRUE) -> FALSE
